## Exception Handling in C++

Exception handling is a mechanism for managing errors and unexpected conditions that may arise during program execution. It provides a structured way to handle these exceptions, preventing program crashes and maintaining program flow.

**Key Concepts:**

- **Exception:** An object representing an error or unexpected condition. It typically inherits from the `std::exception` class.
- **Throw:** The act of raising an exception using the `throw` keyword. You can throw any expression that evaluates to an object.
- **Catch:** The act of handling an exception using a `catch` block within a `try` block.
- **Try Block:** A block of code where exceptions may occur.
- **Catch Block:** A block of code that handles a specific type of exception thrown within the `try` block.

**Benefits:**

- **Improved Error Handling:** Exceptions provide a centralized and controlled way to handle errors, leading to more robust and maintainable code.
- **Error Segregation:** Code that handles normal program flow can be separated from code that deals with errors, improving code clarity.
- **Program Resilience:** Exceptions allow programs to recover from errors gracefully and continue execution in some cases.

**Basic Structure:**

```c++
#include <iostream>
#include <exception> // For std::exception

void someFunction() {
  // Code that might throw an exception
  if (/* error condition */) {
    throw std::runtime_error("An error occurred!"); // Throw an exception object
  }
  // Rest of the function logic
}

int main() {
  try {
    someFunction(); // Call the function that might throw
  } catch (const std::exception& e) { // Catch any standard exception
    std::cerr << "Error caught: " << e.what() << std::endl;
  } catch (const std::runtime_error& e) { // Catch specific exception type (optional)
    std::cerr << "Runtime error: " << e.what() << std::endl;
  }

  // Code that continues after handling the exception (if applicable)

  return 0;
}
```

**Explanation:**

1. **`try` Block:** This block encloses the code where exceptions might occur. If an exception is thrown within this block, control jumps to the corresponding `catch` block (if available) for handling.
2. **`catch` Block:** A `catch` block follows a `try` block to handle exceptions that are thrown within it. You can have multiple `catch` blocks to handle different types of exceptions. The `catch` block's parameter specifies the type of exception it can handle.
   - **Catching by Reference:** The parameter of a `catch` block is usually passed by reference (`const std::exception&`). This allows the handler to access the exception object's information, such as the error message using `e.what()`.
   - **Catching Specific Exception Types:** You can specify a specific exception type within the `catch` block parentheses. This allows for more granular handling of different exceptions. For example, `catch (const std::runtime_error& e)` will only catch exceptions of type `std::runtime_error`.
3. **`finally` Block (Optional):**
   - The `finally` block, placed after the `try` block and any `catch` blocks, is an **optional** block.
   - The code within the `finally` block **always executes**, regardless of whether an exception is thrown or not, and even if the program exits via another mechanism (e.g., `return`).
   - It's commonly used to release resources (like closing files, freeing memory) that were acquired in the `try` block, ensuring proper cleanup even in exceptional cases.

**Example with `finally`:**

```c++
#include <iostream>
#include <exception> // For std::exception

void someFunction() {
  // Code that might throw an exception
  if (/* error condition */) {
    throw std::runtime_error("An error occurred!"); // Throw an exception object
  }
  // Rest of the function logic
}

int main() {
  try {
    someFunction(); // Call the function that might throw
  } catch (const std::exception& e) { // Catch any standard exception
    std::cerr << "Error caught: " << e.what() << std::endl;
  } catch (const std::runtime_error& e) { // Catch specific exception type (optional)
    std::cerr << "Runtime error: " << e.what() << std::endl;
  }

  // Code that continues after handling the exception (if applicable)

  return 0;
}



```
